2025-06-25 22:06:27,839 - database_handler - ERROR - 连接MCP服务器失败: Connection closed
2025-06-25 22:06:27,840 - asyncio - ERROR - an error occurred during closing of asynchronous generator <async_generator object stdio_client at 0x000001BEC47ECAC0>
asyncgen: <async_generator object stdio_client at 0x000001BEC47ECAC0>
  + Exception Group Traceback (most recent call last):
  |   File "C:\Users\hp\.conda\envs\mcp_env\lib\site-packages\anyio\_backends\_asyncio.py", line 772, in __aexit__
  |     raise BaseExceptionGroup(
  | exceptiongroup.BaseExceptionGroup: unhandled errors in a TaskGroup (1 sub-exception)
  +-+---------------- 1 ----------------
    | Traceback (most recent call last):
    |   File "C:\Users\hp\.conda\envs\mcp_env\lib\site-packages\mcp\client\stdio\__init__.py", line 179, in stdio_client
    |     yield read_stream, write_stream
    | GeneratorExit
    +------------------------------------

During handling of the above exception, another exception occurred:

Traceback (most recent call last):
  File "C:\Users\hp\.conda\envs\mcp_env\lib\site-packages\mcp\client\stdio\__init__.py", line 172, in stdio_client
    async with (
  File "C:\Users\hp\.conda\envs\mcp_env\lib\site-packages\anyio\_backends\_asyncio.py", line 778, in __aexit__
    if self.cancel_scope.__exit__(type(exc), exc, exc.__traceback__):
  File "C:\Users\hp\.conda\envs\mcp_env\lib\site-packages\anyio\_backends\_asyncio.py", line 457, in __exit__
    raise RuntimeError(
RuntimeError: Attempted to exit cancel scope in a different task than it was entered in
